Workbook

Sheet Cronograma de Pesquisa em Revis
A1: Fase | B1: Atividade / Tarefa | C1: Detalhes & Entregáveis | D1: Início | E1: Prazo Estimado | F1: Data Finalização | G1: Comentário
A2: 0. Prep. | B2: Padronização de Dados | C2: Limpeza da tabela Excel: Unificar nomes de países, técnicas (ex: "Bi-LSTM" = "LSTM") e métricas. | D2: 46057 | E2: 46057
A3: 1. Metod. | B3: Diagrama de Venn | C3: Gerar gráfico de sobreposição entre Google Scholar e IJDSA. | D3: 46058 | E3: 46058 | F3: 46063 | G3: Meus dados não têm sobreposição (1_Sobreposição)
A4: 1. Metod. | B4: Fluxo PRISMA | C4: Finalizar diagrama com números exatos de exclusão (Triagem -> Inclusão).+1 | D4: 46058 | E4: 46058 | F4: 46063
A5: 1. Metod. | B5: Nuvem de Palavras | C5: Extrair textos dos Resumos (Abstracts) e gerar nuvem para validar alinhamento. | D5: 46059 | E5: 46059 | F5: 46073
A6: 2. Biblio. | B6: Pareto de Publicações | C6: Gráfico de barras: Revistas/Conferências por contagem (identificar o "Top Tier"). | D6: 46062 | E6: 46062 | F6: 46073
A7: 2. Biblio. | B7: Mapa Geo-Linguístico | C7: Cruzamento: País dos Autores vs. Idioma do Dataset (focar no viés anglocêntrico). | D7: 46063 | E7: 46063 | F7: 46073
A8: 2. Biblio. | B8: Matriz de Domínios | C8: Heatmap: Domínio (ex: Finanças) x Target (ex: Preço, Volatilidade). | D8: 46064 | E8: 46064 | F8: 46073
A9: 3. Técnica | B9: Heatmap Co-ocorrência | C9: Matriz: Método de Extração (linhas) x Modelo de Regressão (colunas). | D9: 46065 | E9: 46065 | F9: 46073
A10: 3. Técnica | B10: Scatter "Data Hunger" | C10: Gráfico: Tamanho do Dataset (Log N) vs. Categoria NLP (Dense vs. Contextual). | D10: 46066 | E10: 46066
A11: 3. Técnica | B11: Escrita Teórica (P1) | C11: Redação da fundamentação técnica: Técnica #1 (ex: Transformers/BERT). | D11: 46069 | E11: 46069
A12: 3. Técnica | B12: Escrita Teórica (P2) | C12: Redação da fundamentação técnica: Técnica #2 e #3 (ex: SVR, LSTM). | D12: 46070 | E12: 46070
A13: 4. Perf. | B13: Auditoria de Métricas | C13: Tabela de frequência: Quais métricas são usadas? (Crise de padronização) . | D13: 46071 | E13: 46071
A14: 4. Perf. | B14: Cálculo Ganho Relativo | C14: Calcular % de melhoria sobre baseline para cada paper (Tarefa complexa - Parte 1). | D14: 46072 | E14: 46072
A15: 4. Perf. | B15: Cálculo Ganho Relativo | C15: Calcular % de melhoria sobre baseline (Parte 2) + Consolidar gráfico. | D15: 46073 | E15: 46073
A16: 4. Perf. | B16: Clusterização & Tabela | C16: Tabela de Benchmarks agrupada por Domínio (ex: Tabela "Finanças" com MAPE). | D16: 46076 | E16: 46076
A17: 5. Quali. | B17: Tagging (Vant./Limit.) | C17: Ler colunas de texto e criar tags (categorias) para Vantagens e Limitações. | D17: 46077 | E17: 46077
A18: 5. Quali. | B18: Gráficos Qualitativos | C18: Gerar gráficos de barras das tags (ex: "Overfitting" como limitação comum). | D18: 46078 | E18: 46078
A19: 5. Quali. | B19: Contribuição & Inov. | C19: Mapear tipo de contribuição (Nova Arquitetura vs. Nova Aplicação). | D19: 46079 | E19: 46079
A20: Escrita | B20: Síntese dos Resultados | C20: Redação do capítulo de Resultados (unindo os gráficos gerados). | D20: 46080 | E20: 46080
A21: Escrita | B21: Discussão Crítica | C21: Redação da Discussão (focando em Trade-offs, Gaps e Vieses). | D21: 46083 | E21: 46083
... A25: Fim | B25: Marco Final | C25: Versão pronta para submissão/apresentação ao orientador. | D25: 46087 | E25: 46087

Sheet 1_Sobreposição
A1: title | B1: source
A2: <i>SeNSe</i>: embedding alignment via semantic anchors selection | B2: Google Scholar
A3: A MultilingualBERT EmbeddingsApproach in Identifying Factors Influencing Employability Among Pre-University Students
A4: A Pretraining Approach for Small-sample Training Employing Radiographs (PASTER): a Multimodal Transformer Trained by Chest Radiography and Free-text Reports | B4: Google Scholar
A5: A Survey on the Impact of Pre-Trained Language Models in Sentiment Classification Task | B5: Springer International Journal of Data Science and Analytics
A6: A common-specific feature cross-fusion attention mechanism for KGVQA | B6: Springer International Journal of Data Science and Analytics
A7: A comparative study ontf-idffeature weighting method and its analysis using unstructured dataset | B7: Google Scholar
A8: A deep learning-based approach for identifying unresolved questions on Stack Exchange Q &amp;A communities through graph-based communication modelling | B8: Springer International Journal of Data Science and Analytics
A9: A detailed analysis into evaluation metrics for knowledge graph evaluation | B9: Springer International Journal of Data Science and Analytics
A10: A detailed review on word embedding techniques with emphasis onword2vec | B10: Google Scholar
A11: A graph neural network-based machine learning model for sentiment polarity and behavior identification of COVID patients | B11: Springer International Journal of Data Science and Analytics
A12: A hybrid deep learning neural network for early plant disease diagnosis using a real-world Wheat–Barley vision dataset: challenges and solutions | B12: Springer International Journal of Data Science and Analytics
A13: A hybrid framework for fake news detection using transformer models with MASHAP | B13: Springer International Journal of Data Science and Analytics
A14: A hybrid self attentive linearized phrase structured transformer based RNN for financial sentence analysis with sentence level explainability | B14: Google Scholar
A15: A late fusion framework using whale optimization technique and attention-BiLSTM for fake news detection | B15: Springer International Journal of Data Science and Analytics
... A201: … SemEval-2024 Task 1: Evaluating Semantic Textual Relatedness in Low-resource Languages using Various Embedding Methods and Machine LearningRegression… | B201: Google Scholar

Sheet 2_Prisma
A1: index | B1: title | C1: link | D1: year | E1: citations | F1: pdf_link | G1: source | H1: category | I1: qtd | J1: Abstract read | K1: Includes Feature extraction | L1: Text as regression model variables | M1: No mention of regression | N1: No mention of using NLP for supervised Machine Learning | O1: NLP nor Regression are mentioned | P1: Revisto para nova rejeição | Q1: Rejeição nova: "O estudo aborda a tarefa como um problema de classificação (saídas discretas/classes) em vez de regressão (saídas numéricas contínuas)." | R1: Duplicado | S1: Sem acesso | T1: Etapa | V1: Item | W1: Descrição | X1: Total | Y1: Springer International Journal of Data Science and Analytics | Z1: Google Scholar | AB1: =SUM(I:I) -> 291 | AC1: =SUMIFS($I:$I,$G:$G,Y1) -> 172 | AD1: =SUMIFS($I:$I,$G:$G,Z1) -> 119
A2: 1 | B2: <i>SeNSe</i>: embedding alignment via semantic anchors selection | C2: https://link.springer.com/article/10.1007/s41060-024-00522-z | D2: 2024 | E2: -1 | F2: None | G2: Springer International Journal of Data Science and Analytics | H2: ['Dense Embeddings', 'Applied cases'] | I2: =LEN(H2)-LEN(SUBSTITUTE(H2,",",""))+1 -> 2 | J2: TRUE | K2: FALSE | L2: FALSE | M2: TRUE | N2: TRUE | O2: FALSE | T2: =IFERROR(IFS(K2=FALSE,"IC III",L2=FALSE,"IC IV",M2=TRUE,"EC I",N2=TRUE,"EC II",O2=TRUE,"EC III",R2>0,"EC IV",Q2=TRUE,"EC V",S2<>"","SA"),"OK") -> IC III | V2: IC III | W2: Artigos que aplicam ou descrevem métodos de extração de características textuais. | X2: =SUMIFS(I:I,T:T,V2) -> 49 | Y2: =SUMIFS($I:$I,$T:$T,$V2,$G:$G,Y$1) -> 40 | Z2: =SUMIFS($I:$I,$T:$T,$V2,$G:$G,Z$1) -> 9 | AB2: =AB1-X2 -> 242 | AC2: =AC1-Y2 -> 132 | AD2: =AD1-Z2 -> 110
A3: =A2+1 -> 2 | B3: A MultilingualBERT EmbeddingsApproach in Identifying Factors Influencing Employability Among Pre-University Students | C3: https://ieeexplore.ieee.org/abstract/document/10730172/ | D3: 2024 | E3: 2 | F3: nan | G3: Google Scholar | H3: ['Contextual Embeddings'] | I3: =LEN(H3)-LEN(SUBSTITUTE(H3,",",""))+1 -> 1 | J3: TRUE | K3: TRUE | L3: TRUE | M3: FALSE | N3: FALSE | O3: FALSE | P3: TRUE | Q3: TRUE | T3: =IFERROR(IFS(K3=FALSE,"IC III",L3=FALSE,"IC IV",M3=TRUE,"EC I",N3=TRUE,"EC II",O3=TRUE,"EC III",R3>0,"EC IV",Q3=TRUE,"EC V",S3<>"","SA"),"OK") -> EC V | V3: IC IV | W3: Artigos que usam texto como variável para modelos de regressão. | X3: =SUMIFS(I:I,T:T,V3) -> 192 | Y3: =SUMIFS($I:$I,$T:$T,$V3,$G:$G,Y$1) -> 120 | Z3: =SUMIFS($I:$I,$T:$T,$V3,$G:$G,Z$1) -> 72 | AB3: =AB2-X3 -> 50 | AC3: =AC2-Y3 -> 12 | AD3: =AD2-Z3 -> 38
A4: =A3+1 -> 3 | B4: A Pretraining Approach for Small-sample Training Employing Radiographs (PASTER): a Multimodal Transformer Trained by Chest Radiography and Free-text Reports | C4: https://link.springer.com/article/10.1007/s10916-025-02263-3 | D4: 2025 | E4: 1 | F4: https://linchin.ndmctsgh.edu.tw/papers/2025/2025%20Journal%20of%20Medical%20System.%2049(1)%20120%20(cor).pdf | G4: Google Scholar | H4: ['Contextual Embeddings'] | I4: =LEN(H4)-LEN(SUBSTITUTE(H4,",",""))+1 -> 1 | J4: TRUE | K4: TRUE | L4: TRUE | M4: FALSE | N4: FALSE | O4: FALSE | P4: TRUE | Q4: TRUE | T4: =IFERROR(IFS(K4=FALSE,"IC III",L4=FALSE,"IC IV",M4=TRUE,"EC I",N4=TRUE,"EC II",O4=TRUE,"EC III",R4>0,"EC IV",Q4=TRUE,"EC V",S4<>"","SA"),"OK") -> EC V | V4: EC I | W4: Trabalhos sem aplicação direta em modelos de regressão. | X4: =SUMIFS(I:I,T:T,V4) -> 1 | Y4: =SUMIFS($I:$I,$T:$T,$V4,$G:$G,Y$1) -> 1 | Z4: =SUMIFS($I:$I,$T:$T,$V4,$G:$G,Z$1) -> 0 | AB4: =AB3-X4 -> 49 | AC4: =AC3-Y4 -> 11 | AD4: =AD3-Z4 -> 38
A5: =A4+1 -> 4 | B5: A Survey on the Impact of Pre-Trained Language Models in Sentiment Classification Task | C5: https://link.springer.com/article/10.1007/s41060-025-00805-z | D5: 2025 | E5: -1 | F5: None | G5: Springer International Journal of Data Science and Analytics | H5: ['Classic Methods', 'Dense Embeddings', 'Comparison of methods', 'Literature Reviews', 'Applied cases'] | I5: =LEN(H5)-LEN(SUBSTITUTE(H5,",",""))+1 -> 5 | J5: TRUE | K5: TRUE | L5: FALSE | M5: TRUE | N5: FALSE | O5: FALSE | T5: =IFERROR(IFS(K5=FALSE,"IC III",L5=FALSE,"IC IV",M5=TRUE,"EC I",N5=TRUE,"EC II",O5=TRUE,"EC III",R5>0,"EC IV",Q5=TRUE,"EC V",S5<>"","SA"),"OK") -> IC IV | V5: EC II | W5: Artigos puramente teóricos de NLP sem relação com representação de texto para machine learning supervisionado. | X5: =SUMIFS(I:I,T:T,V5) -> 0 | Y5: =SUMIFS($I:$I,$T:$T,$V5,$G:$G,Y$1) -> 0 | Z5: =SUMIFS($I:$I,$T:$T,$V5,$G:$G,Z$1) -> 0 | AB5: =AB4-X5 -> 49 | AC5: =AC4-Y5 -> 11 | AD5: =AD4-Z5 -> 38
A6: =A5+1 -> 5 | B6: A common-specific feature cross-fusion attention mechanism for KGVQA | C6: https://link.springer.com/article/10.1007/s41060-024-00536-7 | D6: 2024 | E6: -1 | F6: None | G6: Springer International Journal of Data Science and Analytics | H6: ['Dense Embeddings', 'Comparison of methods'] | I6: =LEN(H6)-LEN(SUBSTITUTE(H6,",",""))+1 -> 2 | J6: TRUE | K6: TRUE | L6: FALSE | M6: TRUE | N6: FALSE | O6: FALSE | T6: =IFERROR(IFS(K6=FALSE,"IC III",L6=FALSE,"IC IV",M6=TRUE,"EC I",N6=TRUE,"EC II",O6=TRUE,"EC III",R6>0,"EC IV",Q6=TRUE,"EC V",S6<>"","SA"),"OK") -> IC IV | V6: EC III | W6: Não há menção de NLP e nem regressão no texto. | X6: =SUMIFS(I:I,T:T,V6) -> 0 | Y6: =SUMIFS($I:$I,$T:$T,$V6,$G:$G,Y$1) -> 0 | Z6: =SUMIFS($I:$I,$T:$T,$V6,$G:$G,Z$1) -> 0 | AB6: =AB5-X6 -> 49 | AC6: =AC5-Y6 -> 11 | AD6: =AD5-Z6 -> 38
A7: =A6+1 -> 6 | B7: A comparative study ontf-idffeature weighting method and its analysis using unstructured dataset | C7: https://arxiv.org/abs/2308.04037 | D7: 2023 | E7: 120 | F7: https://arxiv.org/pdf/2308.04037 | G7: Google Scholar | H7: ['Classic Methods'] | I7: =LEN(H7)-LEN(SUBSTITUTE(H7,",",""))+1 -> 1 | J7: TRUE | K7: TRUE | L7: TRUE | M7: FALSE | N7: FALSE | O7: FALSE | P7: TRUE | Q7: TRUE | T7: =IFERROR(IFS(K7=FALSE,"IC III",L7=FALSE,"IC IV",M7=TRUE,"EC I",N7=TRUE,"EC II",O7=TRUE,"EC III",R7>0,"EC IV",Q7=TRUE,"EC V",S7<>"","SA"),"OK") -> EC V | V7: EC IV | W7: Estudos duplicados. | X7: =SUMIFS(I:I,T:T,V7)+SUM(X13:X15) -> 8 | Y7: =SUMIFS($I:$I,$T:$T,$V7,$G:$G,Y$1)+sum(Y13:Y15) -> 5 | Z7: =SUMIFS($I:$I,$T:$T,$V7,$G:$G,Z$1)+SUM(Z13:Z15) -> 3 | AB7: =AB6-X7 -> 41 | AC7: =AC6-Y7 -> 6 | AD7: =AD6-Z7 -> 35
A8: =A7+1 -> 7 | B8: A deep learning-based approach for identifying unresolved questions on Stack Exchange Q &amp;A communities through graph-based communication modelling | C8: https://link.springer.com/article/10.1007/s41060-023-00454-0 | D8: 2023 | E8: -1 | F8: None | G8: Springer International Journal of Data Science and Analytics | H8: ['Contextual Embeddings'] | I8: =LEN(H8)-LEN(SUBSTITUTE(H8,",",""))+1 -> 1 | J8: TRUE | K8: TRUE | L8: FALSE | M8: TRUE | N8: FALSE | O8: TRUE | T8: =IFERROR(IFS(K8=FALSE,"IC III",L8=FALSE,"IC IV",M8=TRUE,"EC I",N8=TRUE,"EC II",O8=TRUE,"EC III",R8>0,"EC IV",Q8=TRUE,"EC V",S8<>"","SA"),"OK") -> IC IV | V8: EC V | W8: O estudo aborda a tarefa como um problema de classificação (saídas discretas/classes) em vez de regressão (saídas numéricas contínuas). | X8: =COUNTIFS(T:T,V8) -> 15 | Y8: =COUNTIFS($T:$T,$V8,$G:$G,Y$1) -> 3 | Z8: =COUNTIFS($T:$T,$V8,$G:$G,Z$1) -> 12 | AB8: =AB7-X8 -> 26 | AC8: =AC7-Y8 -> 3 | AD8: =AD7-Z8 -> 23
A9: =A8+1 -> 8 | B9: A detailed analysis into evaluation metrics for knowledge graph evaluation | C9: https://link.springer.com/article/10.1007/s41060-025-00871-3 | D9: 2025 | E9: -1 | F9: None | G9: Springer International Journal of Data Science and Analytics | H9: ['Applied cases'] | I9: =LEN(H9)-LEN(SUBSTITUTE(H9,",",""))+1 -> 1 | J9: TRUE | K9: FALSE | L9: FALSE | M9: TRUE | N9: FALSE | O9: TRUE | T9: =IFERROR(IFS(K9=FALSE,"IC III",L9=FALSE,"IC IV",M9=TRUE,"EC I",N9=TRUE,"EC II",O9=TRUE,"EC III",R9>0,"EC IV",Q9=TRUE,"EC V",S9<>"","SA"),"OK") -> IC III | V9: SA | W9: Sem acesso | X9: =COUNTIFS(T:T,V9) -> 2 | Y9: =COUNTIFS($T:$T,$V9,$G:$G,Y$1) -> 0 | Z9: =COUNTIFS($T:$T,$V9,$G:$G,Z$1) -> 2 | AB9: =AB8-X9 -> 24 | AC9: =AC8-Y9 -> 3 | AD9: =AD8-Z9 -> 21
A10: =A9+1 -> 9 | B10: A detailed review on word embedding techniques with emphasis onword2vec | C10: https://link.springer.com/article/10.1007/s11042-023-17007-z | D10: 2024 | E10: 176 | F10: nan | G10: Google Scholar | H10: ['Dense Embeddings'] | I10: =LEN(H10)-LEN(SUBSTITUTE(H10,",",""))+1 -> 1 | J10: TRUE | K10: TRUE | L10: FALSE | M10: FALSE | N10: FALSE | O10: FALSE | T10: =IFERROR(IFS(K10=FALSE,"IC III",L10=FALSE,"IC IV",M10=TRUE,"EC I",N10=TRUE,"EC II",O10=TRUE,"EC III",R10>0,"EC IV",Q10=TRUE,"EC V",S10<>"","SA"),"OK") -> IC IV | V10: OK | W10: Ler Completo | X10: =COUNTIFS(T:T,V10) -> 24 | Y10: =COUNTIFS($T:$T,$V10,$G:$G,Y$1) -> 3 | Z10: =COUNTIFS($T:$T,$V10,$G:$G,Z$1) -> 21 | AB10: =AB9-X10 -> 0 | AC10: =AC9-Y10 -> 0 | AD10: =AD9-Z10 -> 0
A11: =A10+1 -> 10 | B11: A graph neural network-based machine learning model for sentiment polarity and behavior identification of COVID patients | C11: https://link.springer.com/article/10.1007/s41060-023-00469-7 | D11: 2023 | E11: -1 | F11: None | G11: Springer International Journal of Data Science and Analytics | H11: ['Literature Reviews', 'Applied cases'] | I11: =LEN(H11)-LEN(SUBSTITUTE(H11,",",""))+1 -> 2 | J11: TRUE | K11: TRUE | L11: TRUE | M11: FALSE | N11: FALSE | O11: FALSE | P11: TRUE | Q11: TRUE | T11: =IFERROR(IFS(K11=FALSE,"IC III",L11=FALSE,"IC IV",M11=TRUE,"EC I",N11=TRUE,"EC II",O11=TRUE,"EC III",R11>0,"EC IV",Q11=TRUE,"EC V",S11<>"","SA"),"OK") -> EC V
A12: =A11+1 -> 11 | B12: A hybrid deep learning neural network for early plant disease diagnosis using a real-world Wheat–Barley vision dataset: challenges and solutions | C12: https://link.springer.com/article/10.1007/s41060-024-00578-x | D12: 2024 | E12: -1 | F12: None | G12: Springer International Journal of Data Science and Analytics | H12: ['Comparison of methods'] | I12: =LEN(H12)-LEN(SUBSTITUTE(H12,",",""))+1 -> 1 | J12: TRUE | K12: TRUE | L12: TRUE | M12: FALSE | N12: FALSE | O12: FALSE | P12: TRUE | Q12: TRUE | T12: =IFERROR(IFS(K12=FALSE,"IC III",L12=FALSE,"IC IV",M12=TRUE,"EC I",N12=TRUE,"EC II",O12=TRUE,"EC III",R12>0,"EC IV",Q12=TRUE,"EC V",S12<>"","SA"),"OK") -> EC V | V12: Duplicados
A13: =A12+1 -> 12 | B13: A hybrid framework for fake news detection using transformer models with MASHAP | C13: https://link.springer.com/article/10.1007/s41060-025-00952-3 | D13: 2025 | E13: -1 | F13: None | G13: Springer International Journal of Data Science and Analytics | H13: ['Classic Methods', 'Dense Embeddings', 'Comparison of methods'] | I13: =LEN(H13)-LEN(SUBSTITUTE(H13,",",""))+1 -> 3 | J13: TRUE | K13: TRUE | L13: FALSE | M13: TRUE | N13: FALSE | O13: FALSE | T13: =IFERROR(IFS(K13=FALSE,"IC III",L13=FALSE,"IC IV",M13=TRUE,"EC I",N13=TRUE,"EC II",O13=TRUE,"EC III",R13>0,"EC IV",Q13=TRUE,"EC V",S13<>"","SA"),"OK") -> IC IV | V13: EC V | X13: =SUMIFS(I:I,T:T,V8)-X8 -> 3 | Y13: =SUMIFS($I:$I,$T:$T,$V8,$G:$G,Y$1)-Y8 -> 3 | Z13: =SUMIFS($I:$I,$T:$T,$V8,$G:$G,Z$1)-Z8 -> 0
A14: =A13+1 -> 13 | B14: A hybrid self attentive linearized phrase structured transformer based RNN for financial sentence analysis with sentence level explainability | C14: https://www.nature.com/articles/s41598-025-09265-8 | D14: 2025 | E14: 7 | F14: https://www.nature.com/articles/s41598-025-09265-8.pdf | G14: Google Scholar | H14: ['Applied cases'] | I14: =LEN(H14)-LEN(SUBSTITUTE(H14,",",""))+1 -> 1 | J14: TRUE | K14: TRUE | L14: TRUE | M14: FALSE | N14: FALSE | O14: FALSE | P14: TRUE | Q14: TRUE | T14: =IFERROR(IFS(K14=FALSE,"IC III",L14=FALSE,"IC IV",M14=TRUE,"EC I",N14=TRUE,"EC II",O14=TRUE,"EC III",R14>0,"EC IV",Q14=TRUE,"EC V",S14<>"","SA"),"OK") -> EC V | V14: SA | X14: =SUMIFS(I:I,T:T,V9)-X9 -> 1 | Y14: =SUMIFS($I:$I,$T:$T,$V9,$G:$G,Y$1)-Y9 -> 0 | Z14: =SUMIFS($I:$I,$T:$T,$V9,$G:$G,Z$1)-Z9 -> 1
A15: =A14+1 -> 14 | B15: A late fusion framework using whale optimization technique and attention-BiLSTM for fake news detection | C15: https://link.springer.com/article/10.1007/s41060-024-00515-y | D15: 2024 | E15: -1 | F15: None | G15: Springer International Journal of Data Science and Analytics | H15: ['Classic Methods', 'Dense Embeddings', 'Comparison of methods', 'Applied cases'] | I15: =LEN(H15)-LEN(SUBSTITUTE(H15,",",""))+1 -> 4 | J15: TRUE | K15: TRUE | L15: FALSE | M15: TRUE | N15: FALSE | O15: FALSE | T15: =IFERROR(IFS(K15=FALSE,"IC III",L15=FALSE,"IC IV",M15=TRUE,"EC I",N15=TRUE,"EC II",O15=TRUE,"EC III",R15>0,"EC IV",Q15=TRUE,"EC V",S15<>"","SA"),"OK") -> IC IV | V15: OK | X15: =SUMIFS(I:I,T:T,V10)-X10 -> 2 | Y15: =SUMIFS($I:$I,$T:$T,$V10,$G:$G,Y$1)-Y10 -> 2 | Z15: =SUMIFS($I:$I,$T:$T,$V10,$G:$G,Z$1)-Z10 -> 0
A16: =A15+1 -> 15 | B16: A layer-wise survey on internal modifications in BERT and its variants: techniques, applications, and performance trade-offs | C16: https://link.springer.com/article/10.1007/s41060-025-00986-7 | D16: 2025 | E16: -1 | F16: None | G16: Springer International Journal of Data Science and Analytics | H16: ['Dense Embeddings', 'Contextual Embeddings', 'Literature Reviews', 'Applied cases'] | I16: =LEN(H16)-LEN(SUBSTITUTE(H16,",",""))+1 -> 4 | J16: TRUE | K16: TRUE | L16: FALSE | M16: TRUE | N16: TRUE | O16: FALSE | T16: =IFERROR(IFS(K16=FALSE,"IC III",L16=FALSE,"IC IV",M16=TRUE,"EC I",N16=TRUE,"EC II",O16=TRUE,"EC III",R16>0,"EC IV",Q16=TRUE,"EC V",S16<>"","SA"),"OK") -> IC IV
A17: =A16+1 -> 16 | B17: A novel hybrid support vector machine with firebug swarm optimization | C17: https://link.springer.com/article/10.1007/s41060-024-00520-1 | D17: 2024 | E17: -1 | F17: None | G17: Springer International Journal of Data Science and Analytics | H17: ['Comparison of methods'] | I17: =LEN(H17)-LEN(SUBSTITUTE(H17,",",""))+1 -> 1 | J17: TRUE | K17: FALSE | L17: FALSE | M17: TRUE | N17: TRUE | O17: TRUE | T17: =IFERROR(IFS(K17=FALSE,"IC III",L17=FALSE,"IC IV",M17=TRUE,"EC I",N17=TRUE,"EC II",O17=TRUE,"EC III",R17>0,"EC IV",Q17=TRUE,"EC V",S17<>"","SA"),"OK") -> IC III
A18: =A17+1 -> 17 | B18: Dual layer Cogni-insight deep-mood encoder: a two-tiered approach for depression detection | C18: https://ieeexplore.ieee.org/abstract/document/10516113/ | D18: 2024 | E18: 1 | F18: nan | G18: Google Scholar | H18: ['Literature Reviews'] | I18: =LEN(H18)-LEN(SUBSTITUTE(H18,",",""))+1 -> 1 | J18: TRUE | K18: TRUE | L18: TRUE | M18: FALSE | N18: FALSE | O18: FALSE | P18: TRUE | Q18: TRUE | T18: =IFERROR(IFS(K18=FALSE,"IC III",L18=FALSE,"IC IV",M18=TRUE,"EC I",N18=TRUE,"EC II",O18=TRUE,"EC III",R18>0,"EC IV",Q18=TRUE,"EC V",S18<>"","SA"),"OK") -> EC V
A19: =A18+1 -> 18 | B19: A review of sentiment analysis: tasks, applications, and deep learning techniques | C19: https://link.springer.com/article/10.1007/s41060-024-00594-x | D19: 2024 | E19: -1 | F19: None | G19: Springer International Journal of Data Science and Analytics | H19: ['Classic Methods', 'Dense Embeddings', 'Literature Reviews', 'Applied cases'] | I19: =LEN(H19)-LEN(SUBSTITUTE(H19,",",""))+1 -> 4 | J19: TRUE | K19: TRUE | L19: FALSE | M19: TRUE | N19: FALSE | O19: FALSE | T19: =IFERROR(IFS(K19=FALSE,"IC III",L19=FALSE,"IC IV",M19=TRUE,"EC I",N19=TRUE,"EC II",O19=TRUE,"EC III",R19>0,"EC IV",Q19=TRUE,"EC V",S19<>"","SA"),"OK") -> IC IV
A20: =A19+1 -> 19 | B20: A review of web infodemic analysis and detection trends across multi-modalities using deep neural network | C20: https://link.springer.com/article/10.1007/s41060-025-00727-w | D20: 2025 | E20: -1 | F20: None | G20: Springer International Journal of Data Science and Analytics | H20: ['Classic Methods', 'Dense Embeddings', 'Comparison of methods', 'Literature Reviews', 'Applied cases'] | I20: =LEN(H20)-LEN(SUBSTITUTE(H20,",",""))+1 -> 5 | J20: TRUE | K20: TRUE | L20: FALSE | M20: TRUE | N20: FALSE | O20: FALSE | T20: =IFERROR(IFS(K20=FALSE,"IC III",L20=FALSE,"IC IV",M20=TRUE,"EC I",N20=TRUE,"EC II",O20=TRUE,"EC III",R20>0,"EC IV",Q20=TRUE,"EC V",S20<>"","SA"),"OK") -> IC IV
A21: =A20+1 -> 20 | B21: A selective model for transfer learning in CNNs: optimization of fine-tuning layers | C21: https://link.springer.com/article/10.1007/s41060-024-00697-5 | D21: 2024 | E21: -1 | F21: None | G21: Springer International Journal of Data Science and Analytics | H21: ['Applied cases'] | I21: =LEN(H21)-LEN(SUBSTITUTE(H21,",",""))+1 -> 1 | J21: TRUE | K21: FALSE | L21: FALSE | M21: TRUE | N21: TRUE | O21: TRUE | T21: =IFERROR(IFS(K21=FALSE,"IC III",L21=FALSE,"IC IV",M21=TRUE,"EC I",N21=TRUE,"EC II",O21=TRUE,"EC III",R21>0,"EC IV",Q21=TRUE,"EC V",S21<>"","SA"),"OK") -> IC III
A22: =A21+1 -> 21 | B22: A similarity-based oversampling method for multi-label imbalanced text data | C22: https://link.springer.com/article/10.1007/s41060-025-00966-x | D22: 2025 | E22: -1 | F22: None | G22: Springer International Journal of Data Science and Analytics | H22: ['Dense Embeddings', 'Literature Reviews'] | I22: =LEN(H22)-LEN(SUBSTITUTE(H22,",",""))+1 -> 2 | J22: TRUE | K22: TRUE | L22: FALSE | M22: TRUE | N22: FALSE | O22: FALSE | T22: =IFERROR(IFS(K22=FALSE,"IC III",L22=FALSE,"IC IV",M22=TRUE,"EC I",N22=TRUE,"EC II",O22=TRUE,"EC III",R22>0,"EC IV",Q22=TRUE,"EC V",S22<>"","SA"),"OK") -> IC IV
A23: =A22+1 -> 22 | B23: A survey of approximate big data computing with the random sample partition (RSP) | C23: https://link.springer.com/article/10.1007/s41060-025-00916-7 | D23: 2025 | E23: -1 | F23: None | G23: Springer International Journal of Data Science and Analytics | H23: ['Applied cases'] | I23: =LEN(H23)-LEN(SUBSTITUTE(H23,",",""))+1 -> 1 | J23: TRUE | K23: FALSE | L23: FALSE | M23: TRUE | N23: TRUE | O23: TRUE | T23: =IFERROR(IFS(K23=FALSE,"IC III",L23=FALSE,"IC IV",M23=TRUE,"EC I",N23=TRUE,"EC II",O23=TRUE,"EC III",R23>0,"EC IV",Q23=TRUE,"EC V",S23<>"","SA"),"OK") -> IC III
A24: =A23+1 -> 23 | B24: A survey of sentiment analysis methods based on graph neural network | C24: https://link.springer.com/article/10.1007/s41060-025-00714-1 | D24: 2025 | E24: -1 | F24: None | G24: Springer International Journal of Data Science and Analytics | H24: ['Classic Methods', 'Dense Embeddings', 'Comparison of methods', 'Literature Reviews', 'Applied cases'] | I24: =LEN(H24)-LEN(SUBSTITUTE(H24,",",""))+1 -> 5 | J24: TRUE | K24: TRUE | L24: FALSE | M24: TRUE | N24: FALSE | O24: FALSE | T24: =IFERROR(IFS(K24=FALSE,"IC III",L24=FALSE,"IC IV",M24=TRUE,"EC I",N24=TRUE,"EC II",O24=TRUE,"EC III",R24>0,"EC IV",Q24=TRUE,"EC V",S24<>"","SA"),"OK") -> IC IV
A25: =A24+1 -> 24 | B25: A survey oftext representationand embedding techniques in nlp | C25: https://ieeexplore.ieee.org/abstract/document/10098736/ | D25: 2023 | E25: 267 | F25: https://ieeexplore.ieee.org/iel7/6287639/6514899/10098736.pdf | G25: Google Scholar | H25: ['Classic Methods', 'Comparison of methods'] | I25: =LEN(H25)-LEN(SUBSTITUTE(H25,",",""))+1 -> 2 | J25: TRUE | K25: TRUE | L25: FALSE | M25: TRUE | N25: FALSE | O25: FALSE | T25: =IFERROR(IFS(K25=FALSE,"IC III",L25=FALSE,"IC IV",M25=TRUE,"EC I",N25=TRUE,"EC II",O25=TRUE,"EC III",R25>0,"EC IV",Q25=TRUE,"EC V",S25<>"","SA"),"OK") -> IC IV
A26: =A25+1 -> 25 | B26: A systematic review of machine learning approaches for detecting deceptive activities on social media: methods, challenges, and biases | C26: https://link.springer.com/article/10.1007/s41060-025-00850-8 | D26: 2025 | E26: -1 | F26: None | G26: Springer International Journal of Data Science and Analytics | H26: ['Classic Methods', 'Dense Embeddings', 'Applied cases'] | I26: =LEN(H26)-LEN(SUBSTITUTE(H26,",",""))+1 -> 3 | J26: TRUE | K26: TRUE | L26: FALSE | M26: TRUE | N26: FALSE | O26: FALSE | T26: =IFERROR(IFS(K26=FALSE,"IC III",L26=FALSE,"IC IV",M26=TRUE,"EC I",N26=TRUE,"EC II",O26=TRUE,"EC III",R26>0,"EC IV",Q26=TRUE,"EC V",S26<>"","SA"),"OK") -> IC IV
A27: =A26+1 -> 26 | B27: AI and data science for smart emergency, crisis and disaster resilience | C27: https://link.springer.com/article/10.1007/s41060-023-00393-w | D27: 2023 | E27: -1 | F27: None | G27: Springer International Journal of Data Science and Analytics | H27: ['Applied cases'] | I27: =LEN(H27)-LEN(SUBSTITUTE(H27,",",""))+1 -> 1 | J27: TRUE | K27: TRUE | L27: FALSE | M27: FALSE | N27: FALSE | O27: TRUE | T27: =IFERROR(IFS(K27=FALSE,"IC III",L27=FALSE,"IC IV",M27=TRUE,"EC I",N27=TRUE,"EC II",O27=TRUE,"EC III",R27>0,"EC IV",Q27=TRUE,"EC V",S27<>"","SA"),"OK") -> IC IV
A28: =A27+1 -> 27 | B28: Acoustic andtext featuresanalysis for adult ADHD screening: A data-driven approach utilizing DIVA interview | C28: https://ieeexplore.ieee.org/abstract/document/10445184/ | D28: 2024 | E28: 22 | F28: https://ieeexplore.ieee.org/iel7/6221039/6563131/10445184.pdf | G28: Google Scholar | H28: ['Comparison of methods'] | I28: =LEN(H28)-LEN(SUBSTITUTE(H28,",",""))+1 -> 1 | J28: TRUE | K28: TRUE | L28: TRUE | M28: FALSE | N28: FALSE | O28: FALSE | P28: TRUE | Q28: TRUE | T28: =IFERROR(IFS(K28=FALSE,"IC III",L28=FALSE,"IC IV",M28=TRUE,"EC I",N28=TRUE,"EC II",O28=TRUE,"EC III",R28>0,"EC IV",Q28=TRUE,"EC V",S28<>"","SA"),"OK") -> EC V
A29: =A28+1 -> 28 | B29: Actuarial applications of natural language processing using transformers: Case studies for usingtext featuresin an actuarial context | C29: https://www.cambridge.org/core/journals/british-actuarial-journal/article/actuarial-applications-of-natural-language-processing-using-transformers-case-studies-for-using-text-features-in-an-actuarial-context/FE5758599524A5C5A837BE54A34155C5 | D29: 2024 | E29: 23 | F29: https://www.cambridge.org/core/services/aop-cambridge-core/content/view/FE5758599524A5C5A837BE54A34155C5/S1357321724000023a.pdf/actuarial_applications_of_natural_language_processing_using_transformers_case_studies_for_using_text_features_in_an_actuarial_context.pdf | G29: Google Scholar | H29: ['Dense Embeddings'] | I29: =LEN(H29)-LEN(SUBSTITUTE(H29,",",""))+1 -> 1 | J29: TRUE | K29: TRUE | L29: TRUE | M29: FALSE | N29: FALSE | O29: FALSE | P29: TRUE | Q29: TRUE | T29: =IFERROR(IFS(K29=FALSE,"IC III",L29=FALSE,"IC IV",M29=TRUE,"EC I",N29=TRUE,"EC II",O29=TRUE,"EC III",R29>0,"EC IV",Q29=TRUE,"EC V",S29<>"","SA"),"OK") -> EC V
A30: =A29+1 -> 29 | B30: Adequate Prompting Improves Performance of Regression Models of Emotional Content | C30: https://dl.acm.org/doi/abs/10.1145/3677525.3678653 | D30: 2024 | E30: 1 | F30: https://dl.acm.org/doi/pdf/10.1145/3677525.3678653 | G30: Google Scholar | H30: ['General'] | I30: =LEN(H30)-LEN(SUBSTITUTE(H30,",",""))+1 -> 1 | J30: TRUE | K30: TRUE | L30: TRUE | M30: FALSE | N30: FALSE | O30: FALSE | P30: TRUE | Q30: FALSE | T30: =IFERROR(IFS(K30=FALSE,"IC III",L30=FALSE,"IC IV",M30=TRUE,"EC I",N30=TRUE,"EC II",O30=TRUE,"EC III",R30>0,"EC IV",Q30=TRUE,"EC V",S30<>"","SA"),"OK") -> OK
A31: =A30+1 -> 30 | B31: Advancements in Large-Scale Image andText RepresentationLearning: A ComprehensiveReviewand Outlook | C31: https://ieeexplore.ieee.org/abstract/document/10883956/ | D31: 2025 | E31: 3 | F31: https://ieeexplore.ieee.org/iel8/6287639/6514899/10883956.pdf | G31: Google Scholar | H31: ['Literature Reviews'] | I31: =LEN(H31)-LEN(SUBSTITUTE(H31,",",""))+1 -> 1 | J31: TRUE | K31: TRUE | L31: FALSE | M31: TRUE | N31: FALSE | O31: FALSE | T31: =IFERROR(IFS(K31=FALSE,"IC III",L31=FALSE,"IC IV",M31=TRUE,"EC I",N31=TRUE,"EC II",O31=TRUE,"EC III",R31>0,"EC IV",Q31=TRUE,"EC V",S31<>"","SA"),"OK") -> IC IV
A32: =A31+1 -> 31 | B32: Advancements in feature selection and extraction methods for text mining: a review | C32: https://link.springer.com/article/10.1007/s42452-025-07587-w | D32: 2025 | E32: 2 | F32: https://link.springer.com/content/pdf/10.1007/s42452-025-07587-w.pdf | G32: Google Scholar | H32: ['Dense Embeddings'] | I32: =LEN(H32)-LEN(SUBSTITUTE(H32,",",""))+1 -> 1 | J32: TRUE | K32: TRUE | L32: FALSE | M32: TRUE | N32: TRUE | O32: FALSE | T32: =IFERROR(IFS(K32=FALSE,"IC III",L32=FALSE,"IC IV",M32=TRUE,"EC I",N32=TRUE,"EC II",O32=TRUE,"EC III",R32>0,"EC IV",Q32=TRUE,"EC V",S32<>"","SA"),"OK") -> IC IV
A33: =A32+1 -> 32 | B33: Empirical assessment of transformer-based neural network architecture in forecasting pollution trends | C33: https://link.springer.com/article/10.1007/s41060-023-00421-9 | D33: 2023 | E33: -1 | F33: None | G33: Springer International Journal of Data Science and Analytics | H33: ['Applied cases'] | I33: =LEN(H33)-LEN(SUBSTITUTE(H33,",",""))+1 -> 1 | J33: TRUE | K33: FALSE | L33: FALSE | M33: FALSE | N33: TRUE | O33: FALSE | P33: TRUE | Q33: FALSE | T33: =IFERROR(IFS(K33=FALSE,"IC III",L33=FALSE,"IC IV",M33=TRUE,"EC I",N33=TRUE,"EC II",O33=TRUE,"EC III",R33>0,"EC IV",Q33=TRUE,"EC V",S33<>"","SA"),"OK") -> IC III
A34: =A33+1 -> 33 | B34: An accurate spam email detection mechanism using XLNet | C34: https://link.springer.com/article/10.1007/s41060-025-00887-9 | D34: 2025 | E34: -1 | F34: None | G34: Springer International Journal of Data Science and Analytics | H34: ['Dense Embeddings', 'Literature Reviews'] | I34: =LEN(H34)-LEN(SUBSTITUTE(H34,",",""))+1 -> 2 | J34: TRUE | K34: FALSE | L34: FALSE | M34: TRUE | N34: FALSE | O34: FALSE | T34: =IFERROR(IFS(K34=FALSE,"IC III",L34=FALSE,"IC IV",M34=TRUE,"EC I",N34=TRUE,"EC II",O34=TRUE,"EC III",R34>0,"EC IV",Q34=TRUE,"EC V",S34<>"","SA"),"OK") -> IC III
A35: =A34+1 -> 34 | B35: An approach for web content classification withFastText | C35: https://link.springer.com/chapter/10.1007/978-981-97-0669-3_14 | D35: 2023 | E35: 5 | F35: nan | G35: Google Scholar | H35: ['Dense Embeddings'] | I35: =LEN(H35)-LEN(SUBSTITUTE(H35,",",""))+1 -> 1 | J35: TRUE | K35: TRUE | L35: FALSE | M35: TRUE | N35: FALSE | O35: FALSE | T35: =IFERROR(IFS(K35=FALSE,"IC III",L35=FALSE,"IC IV",M35=TRUE,"EC I",N35=TRUE,"EC II",O35=TRUE,"EC III",R35>0,"EC IV",Q35=TRUE,"EC V",S35<>"","SA"),"OK") -> IC IV
A36: =A35+1 -> 35 | B36: An extended survey concerning the significance of artificial intelligence and machine learning techniques for bug triage and management | C36: https://ieeexplore.ieee.org/abstract/document/10305170/ | D36: 2023 | E36: 17 | F36: https://ieeexplore.ieee.org/iel7/6287639/6514899/10305170.pdf | G36: Google Scholar | H36: ['General'] | I36: =LEN(H36)-LEN(SUBSTITUTE(H36,",",""))+1 -> 1 | J36: TRUE | K36: FALSE | L36: FALSE | M36: TRUE | N36: FALSE | O36: TRUE | T36: =IFERROR(IFS(K36=FALSE,"IC III",L36=FALSE,"IC IV",M36=TRUE,"EC I",N36=TRUE,"EC II",O36=TRUE,"EC III",R36>0,"EC IV",Q36=TRUE,"EC V",S36<>"","SA"),"OK") -> IC III
A37: =A36+1 -> 36 | B37: An innovative method for accurate NBA player performance forecasting and line-up optimization in daily fantasy sports | C37: https://link.springer.com/article/10.1007/s41060-024-00523-y | D37: 2024 | E37: -1 | F37: None | G37: Springer International Journal of Data Science and Analytics | H37: ['Applied cases'] | I37: =LEN(H37)-LEN(SUBSTITUTE(H37,",",""))+1 -> 1 | J37: TRUE | K37: FALSE | L37: FALSE | M37: FALSE | N37: TRUE | O37: FALSE | T37: =IFERROR(IFS(K37=FALSE,"IC III",L37=FALSE,"IC IV",M37=TRUE,"EC I",N37=TRUE,"EC II",O37=TRUE,"EC III",R37>0,"EC IV",Q37=TRUE,"EC V",S37<>"","SA"),"OK") -> IC III
A38: =A37+1 -> 37 | B38: An overview of methods and techniques in multimodal data fusion with application to healthcare | C38: https://link.springer.com/article/10.1007/s41060-025-00715-0 | D38: 2025 | E38: -1 | F38: None | G38: Springer International Journal of Data Science and Analytics | H38: ['Literature Reviews'] | I38: =LEN(H38)-LEN(SUBSTITUTE(H38,",",""))+1 -> 1 | J38: TRUE | K38: FALSE | L38: FALSE | M38: FALSE | N38: TRUE | O38: FALSE | T38: =IFERROR(IFS(K38=FALSE,"IC III",L38=FALSE,"IC IV",M38=TRUE,"EC I",N38=TRUE,"EC II",O38=TRUE,"EC III",R38>0,"EC IV",Q38=TRUE,"EC V",S38<>"","SA"),"OK") -> IC III
A39: =A38+1 -> 38 | B39: An overview of sentence ordering task | C39: https://link.springer.com/article/10.1007/s41060-024-00550-9 | D39: 2024 | E39: -1 | F39: None | G39: Springer International Journal of Data Science and Analytics | H39: ['Literature Reviews'] | I39: =LEN(H39)-LEN(SUBSTITUTE(H39,",",""))+1 -> 1 | J39: TRUE | K39: TRUE | L39: FALSE | M39: TRUE | N39: FALSE | O39: FALSE | T39: =IFERROR(IFS(K39=FALSE,"IC III",L39=FALSE,"IC IV",M39=TRUE,"EC I",N39=TRUE,"EC II",O39=TRUE,"EC III",R39>0,"EC IV",Q39=TRUE,"EC V",S39<>"","SA"),"OK") -> IC IV
A40: =A39+1 -> 39 | B40: Analysis of the Arab singer Shadia’s lyrics | C40: https://link.springer.com/article/10.1007/s41060-024-00669-9 | D40: 2024 | E40: -1 | F40: None | G40: Springer International Journal of Data Science and Analytics | H40: ['Classic Methods', 'Dense Embeddings', 'Applied cases'] | I40: =LEN(H40)-LEN(SUBSTITUTE(H40,",",""))+1 -> 3 | J40: TRUE | K40: TRUE | L40: FALSE | M40: TRUE | N40: FALSE | O40: FALSE | T40: =IFERROR(IFS(K40=FALSE,"IC III",L40=FALSE,"IC IV",M40=TRUE,"EC I",N40=TRUE,"EC II",O40=TRUE,"EC III",R40>0,"EC IV",Q40=TRUE,"EC V",S40<>"","SA"),"OK") -> IC IV
...

Sheet 3_Dados
A1: Identificação
A2: ID
A3: Código do artigo (ex: A01, A02). | B3: Ano de publicação (filtro: $\geq$ 2023). | C3: Nome completo do trabalho. | D3: Google Scholar ou IJDSA. | E3: URL | F3: Nacionalidade Autores | G3: Revista | H3: Idioma Dataset | I3: Domínio | J3: Target | K3: Embeddings | L3: Estratégia | M3: Tunning | N3: Classe modelo | O3: Tamanho Dataset | P3: Métricas | Q3: Vantagens | R3: Limitações | S3: Contribuições | T3: Ganho Relativo ao Baseline
A4: 1 | B4: 2024 | C4: Adequate Prompting Improves Performance of Regression Models of Emotional Content | D4: Google Scholar | E4: =VLOOKUP(C4,'2_Prisma'!B:C,2,0) -> https://dl.acm.org/doi/abs/10.1145/3677525.3678653 | F4: Italy | G4: Association for Computing Machinery | H4: English, Italian | I4: Psychology | J4: VAD | K4: Contextual | L4: Sentence | M4: Fine-Tuning | N4: Deep Learning & Neural Networks | O4: "10548", "10062" | P4: Pearson Correlation | Q4: Does not require an exclusive dataset, Better metrics | R4: Transparency | S4: Methodological Application, Fine-tuning | T4: =AVERAGE(0.844/0.838,0.587/0.573,0.539/0.536)-1 -> 0.012396576
A5: =A4+1 -> 2 | B5: 2023 | C5: Dating Greek papyri withtext regression | D5: Google Scholar | E5: =VLOOKUP(C5,'2_Prisma'!B:C,2,0) -> https://aclanthology.org/2023.acl-long.556/ | F5: Greece, Sweeden, Switzerland, Italy | G5: Association for Computational Linguistics | H5: Greek | I5: Palaeography | J5: Century of document | K5: Classical | L5: Token, Sentence | M5: Fine-Tuning | N5: Linear & Statistical Models, Tree-Based & Ensemble Models | O5: "389" | P5: MAE, MSE, R² | Q5: Human effort reduction, Novel Use Case | R5: Data loss, Data Quality, Data Availability | S5: Dataset/Resource, Methodological Application | T5: =AVERAGE(1/(0.54/0.91),1/(1.17/1.91),84.64/76.59)-1 -> 0.47425631
A6: =A5+1 -> 3 | B6: 2023 | C6: Designing a forecasting assistant of the Bitcoin price based on deep learning using market sentiment analysis and multiple feature extraction | D6: Google Scholar | E6: =VLOOKUP(C6,'2_Prisma'!B:C,2,0) -> https://link.springer.com/article/10.1007/s00500-023-09028-5 | F6: Iran | G6: Springer Soft Computing | H6: English | I6: Finance | J6: Bitcoin Closing Price of Next Day | K6: Hybrid | L6: Token, Document | M6: Fine-Tuning | N6: Deep Learning & Neural Networks, Deep Learning (Sequential, Recurrent, & Attention) | O6: "1200000" | P6: R², MSE, RMSE, MedAE | Q6: Better metrics | R6: Lack of benchmarks, Lack of transparency | S6: Multimodal Integration | T6: 0
A7: =A6+1 -> 4 | B7: 2024 | C7: Investigation of graph-based clustering approaches along with graph neural networks for modeling armed conflict in Bangladesh | D7: Springer International Journal of Data Science and Analytics | E7: =VLOOKUP(C7,'2_Prisma'!B:C,2,0) -> https://link.springer.com/article/10.1007/s41060-024-00572-3 | F7: Bangladesh | G7: Springer International Journal of Data Science and Analytics | H7: English | I7: Political Science | J7: Fatality Count | K7: Hybrid | L7: Token | M7: Fine-Tuning | N7: Deep Learning & Neural Networks | O7: "13383" | P7: R², MSE, RMSE | Q7: Captures relational dependencies, Performs well with reduced features or sparse data | R7: Computational Complexity, Sensibility to Biases, Data Dimensionality | S7: Methodological Application | T7: =AVERAGE(0.86/0.92)-1 -> -0.065217391 | U7: The model with 93% R² is in a distinct setup | Only gives R² for final model
A8: =A7+1 -> 5 | B8: 2023 | C8: Embeddingregression: Models for context-specific description and inference | D8: Google Scholar | E8: =VLOOKUP(C8,'2_Prisma'!B:C,2,0) -> https://www.cambridge.org/core/journals/american-political-science-review/article/embedding-regression-models-for-contextspecific-description-and-inference/4C90013E5C714C8483ED95CC699022FB | F8: United States | G8: American Political Science Review | H8: English | I8: Political Science | J8: Embedding Vector | K8: Hybrid | L8: Token | M8: Frozen | N8: Linear & Statistical Models | O8: "400", "71" | P8: Cluster Homogeneity, Cosine Similarity, Coefficient Norm | Q8: Sample Efficiency, Speed, Transparency | R8: Assumption of Stability, Data Availability, Pretraining Dependence | S8: New Framework, Domain Insight | T8: 0
A9: =A8+1 -> 6 | B9: 2023 | C9: Enhancing textual relatedness assessment with combined transformers-embedding similarity techniques and machine learning regressors | D9: Google Scholar | E9: =VLOOKUP(C9,'2_Prisma'!B:C,2,0) -> https://ieeexplore.ieee.org/abstract/document/10217726/ | F9: Egypt | G9: Intelligent Methods, Systems, and Applications (IMSA) | H9: English | I9: Natural Language Processing | J9: Relatedness Score | K9: Contextual | L9: Sentence | M9: Frozen | N9: Linear & Statistical Models, Tree-Based & Ensemble Models, Deep Learning & Neural Networks, Instance-Based & Kernel Methods | O9: "9840" | P9: Pearson Correlation, Spearman Correlation, MSE | Q9: Better metrics, Generalize Better | R9: Lack of transparency, Computational Complexity | S9: Feature Engineering | T9: =AVERAGE(1/(0.04809249/0.20241),0.978/0.8969,0.9696/0.8404)-1 -> 1.1509747
A10: =A9+1 -> 7 | B10: 2025 | C10: Forecasting Scientific Impact: A Model for Predicting Citation Counts | D10: Google Scholar | E10: =VLOOKUP(C10,'2_Prisma'!B:C,2,0) -> http://iapress.org/index.php/soic/article/view/2524 | F10: Vietnam | G10: Statistics, Optimization & Information Computing | H10: English | I10: Bibliometrics | J10: Paper Citation Count | K10: Dense | L10: Token | M10: Fine-Tuning | N10: Linear & Statistical Models, Tree-Based & Ensemble Models, Deep Learning & Neural Networks, Deep Learning (Sequential, Recurrent, & Attention) | O10: "1296" | P10: RMSE | Q10: Better Metrics | R10: Sensibility to Biases, Computational Complexity, Data Availability | S10: Methodological Application | T10: =AVERAGE(1/(7.25/11.8))-1 -> 0.62758621
A11: =A10+1 -> 8 | B11: 2025 | C11: Video sentiment analysis on social media using an advanced VADER technique | D11: Springer International Journal of Data Science and Analytics | E11: =VLOOKUP(C11,'2_Prisma'!B:C,2,0) -> https://link.springer.com/article/10.1007/s41060-025-00849-1 | F11: India, Cyprus | G11: Springer International Journal of Data Science and Analytics | H11: English, Hinglish | I11: Social Media | J11: Sentiment Intensity | K11: Hybrid | L11: Sentence | M11: Fine-Tuning | N11: Lexicon / Rule-Based Models | O11: "32800" | P11: MAE, MSE, R² | Q11: Transparency, Speed, Handles slang/emojis/informal text better | R11: Sensibility to Biases, Necessity of Manual Tunning | S11: Feature Engineering, New Pipeline | T11: 0 | U11: No baseline for comparsion in regression
A12: =A11+1 -> 9 | B12: 2025 | C12: A novel sentiment correlation-based method with dual transformer model for stock price prediction | D12: Springer International Journal of Data Science and Analytics | E12: =VLOOKUP(C12,'2_Prisma'!B:C,2,0) -> https://link.springer.com/article/10.1007/s41060-025-00932-7 | F12: Japan | G12: Springer International Journal of Data Science and Analytics | H12: English | I12: Finance | J12: Next day's closing price | K12: Contextual | L12: Document | M12: Fine-Tuning | N12: Deep Learning & Neural Networks | O12: "24000" | P12: MSE | Q12: Captures relational dependencies, Handle Missings | R12: Data Availability, Sensibility to Biases, Necessity of Manual Tunning | S12: New Architecture, Multimodal Integration | T12: =1/AVERAGE(0.002/0.032,0.004/0.029,0.018/0.035,0.032/0.034,0.022/0.037,0.041/0.043,0.032/0.064,0.029/0.038,0.026/0.044,0.022/0.028,0.023/0.041,0.031/0.048,0.009/0.027,0.01/0.026,0.028/0.043,0.035/0.063)-1 -> 0.78268343 | U12: Mean for individual results
A13: =A12+1 -> 10 | B13: 2023 | C13: Read the news, not the books: forecasting firms' long-term financial performance via deep text mining | D13: Google Scholar | E13: =VLOOKUP(C13,'2_Prisma'!B:C,2,0) -> https://dl.acm.org/doi/abs/10.1145/3533018 | F13: United States | G13: Association for Computing Machinery | H13: English | I13: Finance | J13: Companie's Key Financial Indicators | K13: Hybrid | L13: Sentence | M13: Frozen | N13: Traditional Time Series & Econometrics, Deep Learning (Sequential, Recurrent, & Attention) | O13: "778669" | P13: MAPE | Q13: Better metrics, Adaptability, Problem Independent, Transparency | R13: Reliability on Data Quality, Model Can be Optimized, Not Tested on Broader Environmentes | S13: Exploratory Analysis
A14: =A13+1 -> 11 | B14: 2026 | C14: SentiVol-GA: a volatility-scaled genetic fusion of predictive models and financial sentiment for adaptive stock forecasting | D14: Springer International Journal of Data Science and Analytics | E14: =VLOOKUP(C14,'2_Prisma'!B:C,2,0) -> https://link.springer.com/article/10.1007/s41060-025-00983-w | F14: India | G14: Springer International Journal of Data Science and Analytics | H14: English | I14: Finance | J14: Next day's closing price | K14: Hybrid | L14: Sentence | M14: Frozen | N14: Linear & Statistical Models, Tree-Based & Ensemble Models, Deep Learning (Sequential, Recurrent, & Attention), Traditional Time Series & Econometrics | O14: "1250" | P14: R², RMSE, MAE, MSE, Tolerance-Based Accuracy | Q14: Adaptability, Generalization, Better metrics, Transparency | R14: Computational Complexity, Reliability on Data Quality, Complex Design | S14: New Framework, Multimodal Integration
A15: =A14+1 -> 12 | B15: 2023 | C15: Regression applied to legal judgments to predict compensation for immaterial damage | D15: Google Scholar | E15: =VLOOKUP(C15,'2_Prisma'!B:C,2,0) -> https://peerj.com/articles/cs-1225/ | F15: Brazil | G15: PeerJ Computer Science | H15: Brazilian Portuguese | I15: Legal | J15: Monetary value of compensation for immaterial damage | K15: Classical | L15: Document | M15: Frozen | N15: Linear & Statistical Models, Tree-Based & Ensemble Models, Deep Learning & Neural Networks, Instance-Based & Kernel Methods | O15: "928" | P15: R², RMSE, MAE | Q15: Human effort reduction, Better metrics, Novel Use Case | R15: Small Dataset Size | S15: New Framework, Feature Engineering | T15: =AVERAGE(1/(2.464/3.276),1/(1.813/2.596),0.49/0.11,1/(1.812/2.908),1/(890/1.997),0.72/0.3,1/(2.274/3.842),1/(972/2.38),0.56/-0.23,1/(2.355/2.968),1/(1.601/2.27),0.53/0.27,1/(1.75/2.784),1/(915/2.006),0.74/0.36,1/(1.94/2.902),1/(879/2.122),0.68/0.3,1/(2.157/3.031),1/(1.399/2.273),0.61/0.24,1/(1.837/2.914),1/(939/2.004),0.71/0.3,1/(2.423/3.276),1/(1.758/2.445),0.5/0.11,1/(3.54/3.553),1/(2.714/2.75),-0.05/-0.04,1/(1.807/2.912),1/(847/2.059),0.72/0.3)-1 -> 0.41305433
A16: =A15+1 -> 13 | B16: 2025 | C16: Regression in EO: Are VLMs Up to the Challenge? | D16: Google Scholar | E16: =VLOOKUP(C16,'2_Prisma'!B:C,2,0) -> https://arxiv.org/abs/2502.14088 | F16: Germany | G16: arXiv Preprint | H16: English | I16: Geoscience | J16: Continuous geophysical/environmental variables | K16: Contextual | L16: Token | M16: Fine-Tuning | N16: Deep Learning & Neural Networks | P16: N/A | Q16: Transparency, Better Reasoning | R16: Lack of Benchmarks, Cumulative Error Accumulation, Conflict Between Discrete and Continuous Representations | S16: Exploratory Analysis | T16: 0
A17: =A16+1 -> 14 | B17: 2023 | C17: Text Regression Analysis for Predictive Intervals Using Gradient Boosting | D17: Google Scholar | E17: =VLOOKUP(C17,'2_Prisma'!B:C,2,0) -> https://link.springer.com/chapter/10.1007/978-3-031-28073-3_18 | F17: Bulgaria, Germany | G17: Advances in Information and Communication
A18: =A17+1 -> 15 | B18: 2023 | C18: Text‐based soybean futures price forecasting: A two‐stage deep learning approach | D18: Google Scholar | E18: =VLOOKUP(C18,'2_Prisma'!B:C,2,0) -> https://onlinelibrary.wiley.com/doi/abs/10.1002/for.2909 | F18: China | G18: Journal of Forecasting | H18: Chinese | I18: Finance | J18: Soybean Futures Price | K18: Hybrid | L18: Document | M18: Frozen | N18: Deep Learning (Sequential, Recurrent, & Attention) | O18: "795" | P18: MSE, RMSE, MAE, MAPE, SMAPE | Q18: Better Metrics | R18: Data Scope | S18: New Architecture | T18: =AVERAGE(1/(0.008/0.01),1/(0.094/0.102),1/(0.068/0.084),1/(5.891/8.716),1/(6.141/9.875),1/(0.058/0.059))-1 -> 0.27920521 | U18: TSH-LSTM against best for each metric
A19: =A18+1 -> 16 | B19: 2025 | C19: Short and Long-Term Renewable Electricity Demand Forecasting Based on CNN-Bi-GRU Model | D19: Google Scholar | E19: =VLOOKUP(C19,'2_Prisma'!B:C,2,0) -> https://www.icck.org/article/tetai/193/143 | F19: United States | G19: ICCK Transactions on Emerging Topics in Artificial Intelligence | H19: Chinese | I19: Energy | J19: Renewable electricity generation/supply | K19: Hybrid | L19: Token | M19: Frozen | N19: Deep Learning (Sequential, Recurrent, & Attention) | O19: "11342" | P19: RMSE, MAPE, Dstat | Q19: Better metrics, Handle nonlinear and dynamic factors | R19: Transparency, Computational Complexity, Sensibility to Biases, Data Quality | S19: New Architecture, Multimodal Integration | T19: =AVERAGE(1/(6/8),1/(146/220),82/79)-1 -> 0.29271911
A20: =A19+1 -> 17 | B20: 2024 | C20: Text regressionanalysis: A review, empirical, and experimental insights | D20: Google Scholar | E20: =VLOOKUP(C20,'2_Prisma'!B:C,2,0) -> https://ieeexplore.ieee.org/abstract/document/10640097/ | F20: United Arab Emirates | G20: IEEE Access | H20: English (Inferred from dataset sources like Amazon/Yelp/Boston/UCI). | I20: Multidisciplinary | J20: Sentiment scores (reviews), Median home value (housing), Heating/Cooling loads (energy). | K20: Classical | L20: Document | M20: NA | N20: Linear & Statistical Models | O20: "2000000", "8000000", "506", "768" | P20: RMSE | Q20: Better Metrics, Handle Multicolinearity | R20: Data Scope | S20: Systematic Evaluation | T20: 0
A21: =A20+1 -> 18 | B21: 2023 | C21: Interpretable deep learning based textregressionfor financial prediction | D21: Google Scholar | E21: =VLOOKUP(C21,'2_Prisma'!B:C,2,0) -> https://onlinelibrary.wiley.com/doi/abs/10.1111/exsy.13368 | F21: China | G21: Expert Systems | H21: Chinese | I21: Finance | J21: Company ROA | K21: Contextual | L21: Document | M21: Fine-Tuning | N21: Deep Learning & Neural Networks, Deep Learning (Sequential, Recurrent, & Attention) | O21: "594" | P21: MAE, Spearman Correlation | Q21: Novel Use Case, Captures Dynamic Semantic Changes | R21: Reliability on Data Quality | S21: New Architecture | T21: =AVERAGE(1/(1.4736/1.64),0.764/0.6843)-1 -> 0.11469506
A22: =A21+1 -> 19 | B22: 2024 | C22: The effects of sentiment evolution in financial texts: A word embedding approach | D22: Google Scholar | E22: =VLOOKUP(C22,'2_Prisma'!B:C,2,0) -> https://www.tandfonline.com/doi/abs/10.1080/07421222.2023.2301176 | F22: Hong Kong | G22: Journal of Management Information Systems | H22: English | I22: Finance | J22: Excess stock return, Future earnings, Fraud indicator | K22: Dense | L22: Token | M22: Frozen (Embeddings trained yearly on corpus, then used to calculate static intensity scores for regression) | N22: Linear & Statistical Models | O22: "199176", "194928"; "6372781" | P22: Adjusted R², Pseudo R², Coefficients, t-statistics | Q22: Captures Dynamic Semantic Changes, Combines Human Domain Knowledge with Machine Learning, Transparency, Better Metrics | R22: Ignores Data Dependence, Data Scope | S22: New Framework, Domain Insight
A23: =A22+1 -> 20 | B23: 2024 | C23: SMPDF: stock movement prediction based on stock prices and text | D23: Google Scholar | E23: =VLOOKUP(C23,'2_Prisma'!B:C,2,0) -> https://www.tandfonline.com/doi/abs/10.1080/03081079.2023.2294132 | F23: China | G23: International Journal of General Systems
A24: =A23+1 -> 21 | B24: 2024 | C24: [HTML]Enhancing Agile Story Point Estimation: Integrating Deep Learning, Machine Learning, and Natural Language Processing with SBERT and Gradient Boosted … | D24: Google Scholar | E24: =VLOOKUP(C24,'2_Prisma'!B:C,2,0) -> https://www.mdpi.com/2076-3417/14/16/7305 | F24: Türkiye, Australia | G24: Applied Sciences | H24: English | I24: IT | J24: Story Points of Issue Task | K24: Contextual | L24: Documents | M24: Frozen | N24: Tree-Based & Ensemble Models | O24: "31960" | P24: MAE, MdAE, SA | Q24: Better metrics | R24: Data Scope, Model Can be Optimized | S24: Methodological Application, Feature Engineering | T24: 0.12 | U24: On MAE (pg. 3)
A25: =A24+1 -> 22 | B25: 2023 | C25: [HTML]Item difficulty prediction using itemtext features:Comparisonof predictive performance across machine-learning algorithms | D25: Google Scholar | E25: =VLOOKUP(C25,'2_Prisma'!B:C,2,0) -> https://www.mdpi.com/2227-7390/11/19/4104 | F25: Czech Republic | G25: Mathematics | H25: English | I25: Psychology | J25: Item Dificulty | K25: Hybrid | L25: Token (Lemmatized Word) | M25: Fine-Tuning | N25: Linear & Statistical Models, Tree-Based & Ensemble Models, Deep Learning & Neural Networks, Instance-Based & Kernel Methods | O25: "40" | P25: RMSE | Q25: Better metrics, Mathematical Rigor | R25: Small dataset, Conflict Between Discrete and Continuous Representations | S25: Methodological Application | T25: =AVERAGE(1/(0.694/1.004))-1 -> 0.44668588 | U25: RMSE against domain experts
A26: =A25+1 -> 23 | B26: 2025 | C26: [HTML]Using natural language processing to track negative emotions in the daily lives of adolescents | D26: Google Scholar | E26: =VLOOKUP(C26,'2_Prisma'!B:C,2,0) -> https://pmc.ncbi.nlm.nih.gov/articles/PMC12047991/ | F26: United States | G26: NLM Preprint | H26: English | I26: Psychology | J26: Sadness, Anger, Nervousness | K26: Hybrid | L26: Document | M26: Frozen | N26: Linear & Statistical Models, Tree-Based & Ensemble Models | O26: "7680" | P26: R², RMSE | Q26: Better metrics | R26: Modest Overall Predictive Accuracy, Necessity of Large Datasets, Transparency, Data Scope | S26: Methodological Application, Domain Insight | T26: =AVERAGE(0.38/0.17,0.33/0.14,0.2/0.13,0.24/0.11,0.1/0.11,0.1/0.09,0.09/0.07,0.06/0.07,0.1/0.1,0.1/0.1,0.06/0.07,0.08/0.09,1/(0.55/0.64),1/(0.75/0.85),1/(0.69/0.72),1/(0.85/0.92),1/(0.52/0.61),1/(0.73/0.82),1/(0.63/0.88),1/(0.81/0.88),1/(0.47/0.48),1/(0.68/0.69),1/(0.64/0.66),1/(0.75/0.76))-1 -> 0.229366 | U26: Random Forest against Elastic Net
A27: =A26+1 -> 24 | B27: 2025 | C27: [PDF]Financial Market Prediction using Contrastive Learning-based News Representation and Multi-Resolution Market Data | D27: Google Scholar | E27: =VLOOKUP(C27,'2_Prisma'!B:C,2,0) -> https://assets.pubpub.org/p41eo02p/119-01746737674155.pdf | F27: Canada, Iran | G27: The 38th Canadian Conference on Artificial Intelligence | H27: English | I27: Finance | J27: Next day's closing price | K27: Contextual | L27: Sentence, Document | M27: Frozen | N27: Linear & Statistical Models, Deep Learning (Sequential, Recurrent, & Attention) | O27: "7872" | P27: MAPE | Q27: Better metrics, Use of AoE embeddings | R27: Non-stationarity, Sensibility to Biases | S27: New Architecture, Multimodal Integration | T27: =1/AVERAGE(1.058/1.145,1.072/1.161,0.866/0.866,3.273/3.367)-1 -> 0.047273566 | U27: In test
A28: =A27+1 -> 25 | B28: 2023 | C28: [PDF]The implementation ofglovetext embeddings and numerical indicators analysis for plastic resin price prediction | D28: Google Scholar | E28: =VLOOKUP(C28,'2_Prisma'!B:C,2,0) -> http://www.icicel.org/ell/contents/2023/3/el-17-03-01.pdf | F28: Thailand | G28: ICIC Express Letters | H28: English | I28: Industrial | J28: Plastic Resin Price | K28: Dense | L28: Token | M28: Frozen | N28: Traditional Time Series & Econometrics | O28: "371" | P28: RMSE, Test Loss | Q28: Better metrics | R28: Small Dataset Size, Data Quality | S28: New Architecture, Multimodal Integration | T28: 0 | U28: Doesn't have baselines
A29: =A28+1 -> 26 | B29: 2024 | C29: … SemEval-2024 Task 1: Evaluating Semantic Textual Relatedness in Low-resource Languages using Various Embedding Methods and Machine LearningRegression… | D29: Google Scholar | E29: =VLOOKUP(C29,'2_Prisma'!B:C,2,0) -> https://aclanthology.org/2024.semeval-1.65/ | F29: Mexico | G29: Association for Computational Linguistics | H29: Algerian Arabic, Amharic, Hausa, Kinyarwanda, Moroccan Arabic, Marathi, Telugu, Spanish, and English | I29: Natural Language Processing | J29: Semantic Relatedness Score | K29: Hybrid | L29: Sentence | M29: Frozen | N29: Linear & Statistical Models, Tree-Based & Ensemble Models, Deep Learning & Neural Networks, Instance-Based & Kernel Methods | O29: "7795" | P29: Spearman correlation | Q29: Better metrics | R29: Linguistic Ambiguities, Cultural Nuances, Data Availability | S29: Systematic Evaluation | T29: 0 | U29: Doesn't have baselines

Sheet 4_WordCloud
A1: Identificação
A2: ID
A3: Código do artigo (ex: A01, A02). | B3: Ano de publicação (filtro: $\geq$ 2023). | C3: Nome completo do trabalho. | D3: Google Scholar ou IJDSA. | E3: URL | F3: Abstract
A4: 1 | B4: 2024 | C4: Adequate Prompting Improves Performance of Regression Models of Emotional Content | D4: Google Scholar | E4: =VLOOKUP(C4,'2_Prisma'!B:C,2,0) -> https://dl.acm.org/doi/abs/10.1145/3677525.3678653 | F4: Regression models of natural language content are widely popular in many applications, such as sentiment analysis, stance detection and emotion detection. The multidimensional Russell and Mehrabian’s Valence-Arousal-Dominance (VAD) model has been universally recognized as a valuable tool for describing emotional content. Standard methods for VAD prediction learn the relation between natural language text and VAD values by fine-tuning a pre-trained machine learning model based on Transformers (e.g. BERT) on a corpus of natural language sentences manually annotated with VAD. We investigate the potential of employing effective prompting, a technique previously proven to be advantageous in classification and other natural language processing (NLP) tasks, to enhance the VAD prediction process. Our findings reveal that with appropriate prompting, we can leverage the knowledge acquired during pre-training to improve regression performance, showcasing the benefits of this approach for VAD prediction.
A5: =A4+1 -> 2 | B5: 2023 | C5: Dating Greek papyri withtext regression | D5: Google Scholar | E5: =VLOOKUP(C5,'2_Prisma'!B:C,2,0) -> https://aclanthology.org/2023.acl-long.556/ | F5: Dating Greek papyri accurately is crucial not only to edit their texts but also to understand numerous other aspects of ancient writing, document and book production and circulation, as well as various other aspects of administration, everyday life and intellectual history of antiquity. Although a substantial number of Greek papyri documents bear a date or other conclusive data as to their chronological placement, an even larger number can only be dated tentatively or in approximation, due to the lack of decisive evidence. By creating a dataset of 389 transcriptions of documentary Greek papyri, we train 389 regression models and we predict a date for the papyri with an average MAE of 54 years and an MSE of 1.17, outperforming image classifiers and other baselines. Last, we release date estimations for 159 manuscripts, for which only the upper limit is known.
A6: =A5+1 -> 3 | B6: 2023 | C6: Designing a forecasting assistant of the Bitcoin price based on deep learning using market sentiment analysis and multiple feature extraction | D6: Google Scholar | E6: =VLOOKUP(C6,'2_Prisma'!B:C,2,0) -> https://link.springer.com/article/10.1007/s00500-023-09028-5 | F6: Nowadays, the issue of fluctuations in the price of digital Bitcoin currency has a striking impact on the profit or loss of people, international relations, and trade. Accordingly, designing a model that can take into account the various significant factors for predicting the Bitcoin price with the highest accuracy is essential. Hence, the current paper uses market sentiment and multiple feature extraction to present several Bitcoin price prediction models based on convolutional neural network and long short-term memory. In the proposed models, several parameters, including Twitter data, news headlines, news content, Google Trends, Bitcoin-based stock, and finance, are employed based on deep learning to make a more accurate prediction. Such parameters are the input data used to predict the Bitcoin price. Besides, the proposed model analyzes the Valence Aware Dictionary and Sentiment Reasoner sentiments to examine the market’s latest news and cryptocurrencies. According to this study’s various inputs and analyses, several effective feature selection methods, including mutual information regression, linear regression, correlation-based, and a combination of the feature selection models, are exploited to predict the price of Bitcoin. Finally, a careful comparison is made between the proposed models in terms of some performance criteria like mean square error (MSE), root-mean-square error, mean absolute error, median absolute error, and coefficient of determination (R2). The obtained results indicate that the proposed hybrid model based on sentiments analysis and combined feature selection with MSE value of 0.001 and R2 value of 0.98 provides better estimations with more minor errors regarding Bitcoin price. This proposed model can also be employed as an individual assistant for more informed trading decisions associated with Bitcoin.
